try {
    throw new Error("try catch invoked");
} catch (e) {
    console.log(e);
}